import XCTest
@testable import Alicerce

extension MockNetworkStack: NetworkStore {
    public typealias StoreError = NetworkPersistableStoreError
}

class NetworkStack_NetworkStoreTestCase: XCTestCase {

    private typealias Resource = MockResource<String>
    private typealias NetworkStoreResult =
        Result<NetworkStoreValue<Resource.Internal, URLResponse>, NetworkPersistableStoreError>

    private enum MockParseError: Error { case ðŸ’© }
    private enum MockOtherError: Error { case ðŸ’¥ }

    private var networkStack: MockNetworkStack!
    private var testResource: Resource!

    override func setUp() {
        super.setUp()

        networkStack = MockNetworkStack()
        testResource = Resource()
    }

    override func tearDown() {
        networkStack = nil
        testResource = nil

        super.tearDown()
    }

    // MARK: Success tests

    func testFetch_WithSuccessResponse_ShouldCallCompletionClosureWithValue() {
        let expectation = self.expectation(description: "testFetch")
        defer { waitForExpectations(timeout: 1.0) }

        testResource.mockDecode = { String(data: $0, encoding: .utf8)! }

        let mockValue = "ðŸŽ‰"
        networkStack.mockData = mockValue.data(using: .utf8)

        let baseURL = URL(string: "http://")!
        let mockResponse = HTTPURLResponse(url: baseURL, statusCode: 200, httpVersion: nil, headerFields: nil)!
        networkStack.mockResponse = mockResponse

        networkStack.fetch(resource: testResource) { (result: NetworkStoreResult) in

            switch result {
            case .success(.network(let value, let response)):
                XCTAssertEqual(value, mockValue)
                XCTAssertEqual(response, mockResponse)
            case .success(let value):
                XCTFail("ðŸ”¥ received unexpected success ðŸ‘‰ \(value) ðŸ˜±")
            case let .failure(error):
                XCTFail("ðŸ”¥ received unexpected error ðŸ‘‰ \(error) ðŸ˜±")
            }

            expectation.fulfill()
        }

        networkStack.runMockFetch()
    }

    // MARK: Error tests

    func testFetch_WithNetworkFailureError_ShouldThrowNetworkError() {
        let expectation = self.expectation(description: "testFetch")
        defer { waitForExpectations(timeout: 1.0) }

        networkStack.mockError = .ðŸ’£

        networkStack.fetch(resource: testResource) { (result: NetworkStoreResult) in

            switch result {
            case .success:
                XCTFail("ðŸ”¥ should throw an error ðŸ¤”")
            case .failure(.network(MockNetworkStack.Error.ðŸ’£)):
                break // expected error
            case let .failure(error):
                XCTFail("ðŸ”¥ received unexpected error ðŸ‘‰ \(error) ðŸ˜±")
            }

            expectation.fulfill()
        }

        networkStack.runMockFetch()
    }

    func testFetch_WithParseErrorInParseAndNilAPIError_ShouldThrowParseError() {
        let expectation = self.expectation(description: "testFetch")
        defer { waitForExpectations(timeout: 1.0) }

        testResource.mockDecode = { _ in throw Parse.Error.json(MockParseError.ðŸ’©) }
        testResource.mockDecodeError = { _, _ in nil }

        networkStack.mockData = "ðŸ¤”".data(using: .utf8)

        networkStack.fetch(resource: testResource) { (result: NetworkStoreResult) in

            switch result {
            case .success:
                XCTFail("ðŸ”¥ should throw an error ðŸ¤”")
            case .failure(.decode(Parse.Error.json(MockParseError.ðŸ’©))):
                break // expected error
            case let .failure(error):
                XCTFail("ðŸ”¥ received unexpected error ðŸ‘‰ \(error) ðŸ˜±")
            }

            expectation.fulfill()
        }

        networkStack.runMockFetch()
    }

    func testFetch_WithJSONParseErrorInParseAndNonNilAPIError_ShouldThrowParseErrorWithAPIError() {
        let expectation = self.expectation(description: "testFetch")
        defer { waitForExpectations(timeout: 1.0) }

        testResource.mockDecode = { _ in throw Parse.Error.json(JSON.Error.serialization(MockParseError.ðŸ’©)) }

        networkStack.mockData = "ðŸ¤”".data(using: .utf8)

        networkStack.fetch(resource: testResource) { (result: NetworkStoreResult) in

            switch result {
            case .success:
                XCTFail("ðŸ”¥ should throw an error ðŸ¤”")
            case .failure(.decode(Resource.MockAPIError.ðŸ’©)):
                break // expected error
            case let .failure(error):
                XCTFail("ðŸ”¥ received unexpected error ðŸ‘‰ \(error) ðŸ˜±")
            }

            expectation.fulfill()
        }

        networkStack.runMockFetch()
    }

    func testFetch_WithAnyErrorAndCancelledCancelable_ShouldThrowCancelledError() {
        let expectation = self.expectation(description: "testFetch")
        defer { waitForExpectations(timeout: 1.0) }

        let cancelable = CancelableBag()

        networkStack.mockError = .ðŸ’¥
        networkStack.beforeFetchCompletionClosure = {
            cancelable.cancel()
        }

        cancelable += networkStack.fetch(resource: testResource) { (result: NetworkStoreResult) in

            switch result {
            case .success:
                XCTFail("ðŸ”¥ should throw an error ðŸ¤”")
            case .failure(.cancelled(MockNetworkStack.Error.ðŸ’¥?)):
                 break // expected error
            case let .failure(error):
                XCTFail("ðŸ”¥ received unexpected error ðŸ‘‰ \(error) ðŸ˜±")
            }

            expectation.fulfill()
        }

        networkStack.runMockFetch()
    }
}
