//
//  StoreTestCase.swift
//  Alicerce
//
//  Created by AndrÃ© Pacheco Neves on 27/04/2017.
//  Copyright Â© 2017 Mindera. All rights reserved.
//

import XCTest
@testable import Alicerce

typealias MockStore<T> = DataStore<T, MockPersistenceStack>

struct MockResource: NetworkResource, PersistableResource {
    let value: String
    let parser: (Data) throws -> String

    var persistenceKey: Persistence.Key {
        return value
    }

    func toRequest(withBaseURL baseURL: URL) -> URLRequest {
        return URLRequest(url: URL(string: "http://localhost")!)
    }
}

class StoreTestCase: XCTestCase {

    private let testValue = "ðŸ˜Ž"

    private lazy var testData: Data = {
        return self.testValue.data(using: .utf8)!
    }()

    private lazy var testResource: MockResource = {
        return MockResource(value: self.testValue, parser: { String(data: $0, encoding: .utf8)! })
    }()

    private let expectationTimeout: TimeInterval = 5
    private let expectationHandler: XCWaitCompletionHandler = { error in
        if let error = error {
            XCTFail("ðŸ”¥: Test expectation wait timed out: \(error)")
        }
    }

    var networkStack: MockNetworkStack!
    var persistenceStack: MockPersistenceStack!

    var store: MockStore<String>!
    
    override func setUp() {
        super.setUp()

        networkStack = MockNetworkStack(mockData: testData, mockError: nil)
        persistenceStack = MockPersistenceStack()

        store = MockStore(networkStack: networkStack, persistenceStack: persistenceStack)
    }
    
    override func tearDown() {
        networkStack = nil
        persistenceStack = nil
        store = nil

        super.tearDown()
    }

    // MARK: Failure

    func testFetch_WithFailingNetwork_ShouldFailWithNetworkError() {
        let expectation = self.expectation(description: "testFetch")
        defer { waitForExpectations(timeout: expectationTimeout, handler: expectationHandler) }

        networkStack.mockError = .noData

        store.fetch(resource: testResource) { (value, error, isCached) in
            XCTAssertNil(value)
            XCTAssertFalse(isCached)

            defer { expectation.fulfill() }

            guard let error = error else {
                return XCTFail("ðŸ”¥: unexpected success!")
            }

            guard case .network(Network.Error.noData) = error else {
                return XCTFail("ðŸ”¥: unexpected error \(error)!")
            }
        }
    }

    func testFetch_WithFailingParser_ShouldFailWithParseError() {
        let expectation = self.expectation(description: "testFetch")
        defer { waitForExpectations(timeout: expectationTimeout, handler: expectationHandler) }

        enum TestParseError: Error { case ðŸ’© }

        let failParseResource = MockResource(value: "ðŸ’¥", parser: { _ in throw Parse.Error.json(TestParseError.ðŸ’©) })

        store.fetch(resource: failParseResource) { (value, error, isCached) in
            XCTAssertNil(value)
            XCTAssertFalse(isCached)

            defer { expectation.fulfill() }

            guard let error = error else {
                return XCTFail("ðŸ”¥: unexpected success!")
            }

            guard case .parse(Parse.Error.json(TestParseError.ðŸ’©)) = error else {
                return XCTFail("ðŸ”¥: unexpected error \(error)!")
            }
        }
    }

    func testFetch_WithFailingPersistence_ShouldFailWithParseError() {
        let expectation = self.expectation(description: "testFetch")
        defer { waitForExpectations(timeout: expectationTimeout, handler: expectationHandler) }

        enum TestParseError: Error { case ðŸ’© }

        let failParseResource = MockResource(value: "ðŸ’¥", parser: { _ in throw Parse.Error.json(TestParseError.ðŸ’©) })

        store.fetch(resource: failParseResource) { (value, error, isCached) in
            XCTAssertNil(value)
            XCTAssertFalse(isCached)

            defer { expectation.fulfill() }

            guard let error = error else {
                return XCTFail("ðŸ”¥: unexpected success!")
            }

            guard case .parse(Parse.Error.json(TestParseError.ðŸ’©)) = error else {
                return XCTFail("ðŸ”¥: unexpected error \(error)!")
            }
        }
    }

    func testFetch_WithCachedDataAndFailingParser_ShouldFail() {
        let expectation = self.expectation(description: "testFetch")
        defer { waitForExpectations(timeout: expectationTimeout, handler: expectationHandler) }

        enum TestParseError: Error { case ðŸ’© }

        persistenceStack.mockObjectCompletion = { return self.testData }
        let failParseResource = MockResource(value: "ðŸ’¥", parser: { _ in throw Parse.Error.json(TestParseError.ðŸ’©) })

        store.fetch(resource: failParseResource) { (value, error, isCached) in
            XCTAssertNil(value)
            XCTAssertFalse(isCached)

            defer { expectation.fulfill() }

            guard let error = error else {
                return XCTFail("ðŸ”¥: unexpected success!")
            }

            guard case .parse(Parse.Error.json(TestParseError.ðŸ’©)) = error else {
                return XCTFail("ðŸ”¥: unexpected error \(error)!")
            }
        }
    }

    func testFetch_WithCancelledNetworkFetch_ShouldFailWithCancelledError() {
        let expectation = self.expectation(description: "testFetch")
        defer { waitForExpectations(timeout: expectationTimeout, handler: expectationHandler) }

        networkStack.mockError = .url(NSError(domain: NSURLErrorDomain, code: NSURLErrorCancelled))

        store.fetch(resource: testResource) { (value, error, isCached) in
            XCTAssertNil(value)
            XCTAssertFalse(isCached)

            defer { expectation.fulfill() }

            guard let error = error else {
                return XCTFail("ðŸ”¥: unexpected success!")
            }

            guard case .cancelled = error else {
                return XCTFail("ðŸ”¥: unexpected error \(error)!")
            }
        }
    }

    func testFetchCancel_BeforeParse_ShouldFailWithCancelledError() {
        let expectation = self.expectation(description: "testFetch")
        let expectation2 = self.expectation(description: "fetchCancel")
        defer { waitForExpectations(timeout: expectationTimeout, handler: expectationHandler) }

        networkStack.mockCancelable.mockCancelClosure = {
            expectation2.fulfill()
        }

        let cancelable = store.fetch(resource: testResource) { (value, error, isCached) in
            XCTAssertNil(value)
            XCTAssertFalse(isCached)

            defer { expectation.fulfill() }

            guard let error = error else {
                return XCTFail("ðŸ”¥: unexpected success!")
            }

            guard case .cancelled = error else {
                return XCTFail("ðŸ”¥: unexpected error \(error)!")
            }
        }

        // trigger the cancel before the fetch completion closure is invoked
        networkStack.beforeFetchCompletionClosure = {
            cancelable.cancel()
        }
    }

    func testFetchCancel_BeforePersist_ShouldFailWithCancelledError() {
        let expectation = self.expectation(description: "testFetch")
        let expectation2 = self.expectation(description: "fetchCancel")
        defer { waitForExpectations(timeout: expectationTimeout, handler: expectationHandler) }

        // closure to cancel the cancelable
        var cancelClosure: (() -> Void)?

        let cancellingParse: (Data) -> String = {
            cancelClosure?()
            return String(data: $0, encoding: .utf8)!
        }

        let cancellingParseResource = MockResource(value: self.testValue, parser: cancellingParse)

        networkStack.mockCancelable.mockCancelClosure = {
            expectation2.fulfill()
        }

        let cancelable = store.fetch(resource: cancellingParseResource) { (value, error, isCached) in
            XCTAssertNil(value)
            XCTAssertFalse(isCached)

            defer { expectation.fulfill() }

            guard let error = error else {
                return XCTFail("ðŸ”¥: unexpected success!")
            }

            guard case .cancelled = error else {
                return XCTFail("ðŸ”¥: unexpected error \(error)!")
            }
        }

        // trigger the cancel after the parse closure is invoked
        cancelClosure = {
            cancelable.cancel()
        }
    }

    // MARK: Success

    func testFetch_WithValidData_ShouldSucceed() {
        let expectation = self.expectation(description: "testFetch")
        defer { waitForExpectations(timeout: expectationTimeout, handler: expectationHandler) }

        store.fetch(resource: testResource) { (value, error, isCached) in
            XCTAssertNil(error)
            XCTAssertFalse(isCached)

            defer { expectation.fulfill() }

            guard let value = value else {
                return XCTFail("ðŸ”¥: missing value!")
            }

            XCTAssertEqual(value, self.testValue)
        }
    }

    func testFetch_WithCachedData_ShouldSucceed() {
        let expectation = self.expectation(description: "testFetch")
        defer { waitForExpectations(timeout: expectationTimeout, handler: expectationHandler) }

        persistenceStack.mockObjectCompletion = { return self.testData }

        store.fetch(resource: testResource) { (value, error, isCached) in
            XCTAssertNil(error)
            XCTAssertTrue(isCached)

            defer { expectation.fulfill() }

            guard let value = value else {
                return XCTFail("ðŸ”¥: missing value!")
            }

            XCTAssertEqual(value, self.testValue)
        }
    }

    func testFetch_WithValidDataAndFailingPersistenceGet_ShouldSucceed() {
        let expectation = self.expectation(description: "testFetch")
        defer { waitForExpectations(timeout: expectationTimeout, handler: expectationHandler) }

        enum TestPersistenceError: Error { case ðŸ’¥ }

        persistenceStack.mockObjectCompletion = { _ in throw Persistence.Error.other(TestPersistenceError.ðŸ’¥) }
        persistenceStack.mockSetObjectCompletion = { _ in throw Persistence.Error.other(TestPersistenceError.ðŸ’¥) }

        store.fetch(resource: testResource) { (value, error, isCached) in
            XCTAssertNil(error)
            XCTAssertFalse(isCached)

            defer { expectation.fulfill() }

            guard let value = value else {
                return XCTFail("ðŸ”¥: missing value!")
            }

            XCTAssertEqual(value, self.testValue)
        }
    }
}
